<?xml version="1.0"?>

<robot name="Lewansoul xArm" xmlns="http://www.ros.org">
  
  <!-- Colors -->
  <material name="Grey">
    <color rgba="0.2 0.2 0.2 1.0"/>
  </material>
  <material name="Blue">
    <color rgba="0.5 0.7 1.0 1.0"/>
  </material>
  <material name="Black">
    <color rgba="0 0 0 1.0"/>
  </material>

  <link name="Base">
    <visual>
      <origin rpy="0 0 0" xyz="0 0 0.0275"/>
      <geometry>
        <box size="0.114 0.114 0.055" />
      </geometry>
      <material name="Blue"/>
    </visual>
  </link>
  
  <joint name="BaseRotation" type="revolute">
    <parent link="Base"/>
    <child link="BaseToServo5"/>
    <origin rpy="0 0 0" xyz="0 0 .055"/>
    <axis xyz="0 0 1"/>
    <limit lower="-2.23" upper="2.23" effort="30" velocity="1"/>
  </joint>

  <link name="BaseToServo5">
    <visual>
      <origin rpy="0 0 0" xyz="-.0085 0 .0145"/>
      <geometry>
        <box size=".045 .030 .029"/>
      </geometry>
      <material name="Black"/>
    </visual>
  </link>

  <joint name="Servo5" type="revolute">
    <parent link="BaseToServo5"/>
    <child link="Servo5ToServo4"/>
    <origin rpy="0 0 0" xyz="0 0 .016"/>
    <axis xyz="0 1 0"/>
    <limit lower="-1.763" upper=".9643" effort="30" velocity="1"/>
  </joint>

  <link name="Servo5ToServo4">
    <visual>
      <origin rpy="0 0 0" xyz="0 0 .05"/>
      <geometry>
        <box size=".032 .043 .126"/>
      </geometry>
      <material name="Blue"/>
    </visual>
  </link>
  
  <joint name="Servo4" type="revolute">
    <parent link="Servo5ToServo4"/>
    <child link="Servo4ToServo3"/>
    <origin rpy="0 0 0" xyz="0 0 .096"/>
    <axis xyz="0 1 0"/>
    <limit lower="-2.234" upper="2.129" effort="30" velocity="1"/>
  </joint>

  <link name="Servo4ToServo3">
    <visual>
      <origin rpy="0 0 0" xyz="0 0 .048"/>
      <geometry>
        <box size=".023 .029 .117"/>
      </geometry>
      <material name="Blue"/>
    </visual>
  </link>

  <joint name="Servo3" type="revolute">
    <parent link="Servo4ToServo3"/>
    <child link="Servo3ToGripper"/>
    <origin rpy="0 0 0" xyz="0 0 .1065"/>
    <axis xyz="0 1 0"/>
    <limit lower="-2.234" upper="1.885" effort="30" velocity="1"/>
  </joint>

  <link name="Servo3ToGripper">
    <visual>
      <origin rpy="0 0 0" xyz="0 0 .0195"/>
      <geometry>
        <box size=".023 .042 .063"/>
      </geometry>
      <material name="Blue"/>
    </visual>
    <visual>
      <origin rpy="0 0 0" xyz=".022 0 .0375"/>
      <geometry>
        <box size=".021 .023 .027"/>
      </geometry>
      <material name="Blue"/>
    </visual>
  </link>

  <joint name="GripperRotation" type="revolute">
    <parent link="Servo3ToGripper"/>
    <child link="Gripper"/>
    <origin rpy="0 0 0" xyz="0 0 .051"/>
    <axis xyz="0 0 1"/>
    <limit lower="-2.234" upper="2.129" effort="30" velocity="1"/>
  </joint>

  <link name="Gripper">
    <visual>
      <origin rpy="0 0 0" xyz="0 0 .055"/>
      <geometry>
        <box size=".073 .01 .110"/>
      </geometry>
      <material name="Black"/>
    </visual>
  </link>
</robot>
